2025-10-05 22:53:51,751 INFO: 开始处理 2 个 RSS 源
2025-10-05 22:53:56,791 ERROR: 请求 RSS 源 https://rss.nytimes.com/services/xml/rss/nyt/Technology.xml 时出错: Cannot connect to host rss.nytimes.com:443 ssl:default [Temporary failure in name resolution]
Traceback (most recent call last):
  File "/opt/pyvenv/lib/python3.11/site-packages/aiohttp/connector.py", line 1203, in _create_direct_connection
    hosts = await self._resolve_host(host, port, traces=traces)
            ^^^^^^^^^^^^^^^^^^^^^^^^^^^^^^^^^^^^^^^^^^^^^^^^^^^
  File "/opt/pyvenv/lib/python3.11/site-packages/aiohttp/connector.py", line 880, in _resolve_host
    return await asyncio.shield(resolved_host_task)
           ^^^^^^^^^^^^^^^^^^^^^^^^^^^^^^^^^^^^^^^^
  File "/opt/pyvenv/lib/python3.11/site-packages/aiohttp/connector.py", line 917, in _resolve_host_with_throttle
    addrs = await self._resolver.resolve(host, port, family=self._family)
            ^^^^^^^^^^^^^^^^^^^^^^^^^^^^^^^^^^^^^^^^^^^^^^^^^^^^^^^^^^^^^
  File "/opt/pyvenv/lib/python3.11/site-packages/aiohttp/resolver.py", line 33, in resolve
    infos = await self._loop.getaddrinfo(
            ^^^^^^^^^^^^^^^^^^^^^^^^^^^^^
  File "/usr/lib/python3.11/asyncio/base_events.py", line 867, in getaddrinfo
    return await self.run_in_executor(
           ^^^^^^^^^^^^^^^^^^^^^^^^^^^
  File "/usr/lib/python3.11/concurrent/futures/thread.py", line 58, in run
    result = self.fn(*self.args, **self.kwargs)
             ^^^^^^^^^^^^^^^^^^^^^^^^^^^^^^^^^^
  File "/usr/lib/python3.11/socket.py", line 962, in getaddrinfo
    for res in _socket.getaddrinfo(host, port, family, type, proto, flags):
               ^^^^^^^^^^^^^^^^^^^^^^^^^^^^^^^^^^^^^^^^^^^^^^^^^^^^^^^^^^^
socket.gaierror: [Errno -3] Temporary failure in name resolution

The above exception was the direct cause of the following exception:

Traceback (most recent call last):
  File "/home/oai/share/rss-ai/backend/main.py", line 206, in fetch_and_parse
    async with session.get(rss_url) as resp:
  File "/opt/pyvenv/lib/python3.11/site-packages/aiohttp/client.py", line 1197, in __aenter__
    self._resp = await self._coro
                 ^^^^^^^^^^^^^^^^
  File "/opt/pyvenv/lib/python3.11/site-packages/aiohttp/client.py", line 581, in _request
    conn = await self._connector.connect(
           ^^^^^^^^^^^^^^^^^^^^^^^^^^^^^^
  File "/opt/pyvenv/lib/python3.11/site-packages/aiohttp/connector.py", line 544, in connect
    proto = await self._create_connection(req, traces, timeout)
            ^^^^^^^^^^^^^^^^^^^^^^^^^^^^^^^^^^^^^^^^^^^^^^^^^^^
  File "/opt/pyvenv/lib/python3.11/site-packages/aiohttp/connector.py", line 944, in _create_connection
    _, proto = await self._create_direct_connection(req, traces, timeout)
               ^^^^^^^^^^^^^^^^^^^^^^^^^^^^^^^^^^^^^^^^^^^^^^^^^^^^^^^^^^
  File "/opt/pyvenv/lib/python3.11/site-packages/aiohttp/connector.py", line 1209, in _create_direct_connection
    raise ClientConnectorError(req.connection_key, exc) from exc
aiohttp.client_exceptions.ClientConnectorError: Cannot connect to host rss.nytimes.com:443 ssl:default [Temporary failure in name resolution]
2025-10-05 22:53:59,387 INFO: 配置已更新。
2025-10-05 22:53:59,388 INFO: 开始处理 1 个 RSS 源
2025-10-05 22:54:01,805 ERROR: 请求 RSS 源 https://feeds.bbci.co.uk/news/technology/rss.xml 时出错: Cannot connect to host feeds.bbci.co.uk:443 ssl:default [Temporary failure in name resolution]
Traceback (most recent call last):
  File "/opt/pyvenv/lib/python3.11/site-packages/aiohttp/connector.py", line 1203, in _create_direct_connection
    hosts = await self._resolve_host(host, port, traces=traces)
            ^^^^^^^^^^^^^^^^^^^^^^^^^^^^^^^^^^^^^^^^^^^^^^^^^^^
  File "/opt/pyvenv/lib/python3.11/site-packages/aiohttp/connector.py", line 880, in _resolve_host
    return await asyncio.shield(resolved_host_task)
           ^^^^^^^^^^^^^^^^^^^^^^^^^^^^^^^^^^^^^^^^
  File "/opt/pyvenv/lib/python3.11/site-packages/aiohttp/connector.py", line 917, in _resolve_host_with_throttle
    addrs = await self._resolver.resolve(host, port, family=self._family)
            ^^^^^^^^^^^^^^^^^^^^^^^^^^^^^^^^^^^^^^^^^^^^^^^^^^^^^^^^^^^^^
  File "/opt/pyvenv/lib/python3.11/site-packages/aiohttp/resolver.py", line 33, in resolve
    infos = await self._loop.getaddrinfo(
            ^^^^^^^^^^^^^^^^^^^^^^^^^^^^^
  File "/usr/lib/python3.11/asyncio/base_events.py", line 867, in getaddrinfo
    return await self.run_in_executor(
           ^^^^^^^^^^^^^^^^^^^^^^^^^^^
  File "/usr/lib/python3.11/concurrent/futures/thread.py", line 58, in run
    result = self.fn(*self.args, **self.kwargs)
             ^^^^^^^^^^^^^^^^^^^^^^^^^^^^^^^^^^
  File "/usr/lib/python3.11/socket.py", line 962, in getaddrinfo
    for res in _socket.getaddrinfo(host, port, family, type, proto, flags):
               ^^^^^^^^^^^^^^^^^^^^^^^^^^^^^^^^^^^^^^^^^^^^^^^^^^^^^^^^^^^
socket.gaierror: [Errno -3] Temporary failure in name resolution

The above exception was the direct cause of the following exception:

Traceback (most recent call last):
  File "/home/oai/share/rss-ai/backend/main.py", line 206, in fetch_and_parse
    async with session.get(rss_url) as resp:
  File "/opt/pyvenv/lib/python3.11/site-packages/aiohttp/client.py", line 1197, in __aenter__
    self._resp = await self._coro
                 ^^^^^^^^^^^^^^^^
  File "/opt/pyvenv/lib/python3.11/site-packages/aiohttp/client.py", line 581, in _request
    conn = await self._connector.connect(
           ^^^^^^^^^^^^^^^^^^^^^^^^^^^^^^
  File "/opt/pyvenv/lib/python3.11/site-packages/aiohttp/connector.py", line 544, in connect
    proto = await self._create_connection(req, traces, timeout)
            ^^^^^^^^^^^^^^^^^^^^^^^^^^^^^^^^^^^^^^^^^^^^^^^^^^^
  File "/opt/pyvenv/lib/python3.11/site-packages/aiohttp/connector.py", line 944, in _create_connection
    _, proto = await self._create_direct_connection(req, traces, timeout)
               ^^^^^^^^^^^^^^^^^^^^^^^^^^^^^^^^^^^^^^^^^^^^^^^^^^^^^^^^^^
  File "/opt/pyvenv/lib/python3.11/site-packages/aiohttp/connector.py", line 1209, in _create_direct_connection
    raise ClientConnectorError(req.connection_key, exc) from exc
aiohttp.client_exceptions.ClientConnectorError: Cannot connect to host feeds.bbci.co.uk:443 ssl:default [Temporary failure in name resolution]
2025-10-05 22:54:04,397 ERROR: 请求 RSS 源 http://example.com/rss 时出错: Cannot connect to host example.com:80 ssl:default [Temporary failure in name resolution]
Traceback (most recent call last):
  File "/opt/pyvenv/lib/python3.11/site-packages/aiohttp/connector.py", line 1203, in _create_direct_connection
    hosts = await self._resolve_host(host, port, traces=traces)
            ^^^^^^^^^^^^^^^^^^^^^^^^^^^^^^^^^^^^^^^^^^^^^^^^^^^
  File "/opt/pyvenv/lib/python3.11/site-packages/aiohttp/connector.py", line 880, in _resolve_host
    return await asyncio.shield(resolved_host_task)
           ^^^^^^^^^^^^^^^^^^^^^^^^^^^^^^^^^^^^^^^^
  File "/opt/pyvenv/lib/python3.11/site-packages/aiohttp/connector.py", line 917, in _resolve_host_with_throttle
    addrs = await self._resolver.resolve(host, port, family=self._family)
            ^^^^^^^^^^^^^^^^^^^^^^^^^^^^^^^^^^^^^^^^^^^^^^^^^^^^^^^^^^^^^
  File "/opt/pyvenv/lib/python3.11/site-packages/aiohttp/resolver.py", line 33, in resolve
    infos = await self._loop.getaddrinfo(
            ^^^^^^^^^^^^^^^^^^^^^^^^^^^^^
  File "/usr/lib/python3.11/asyncio/base_events.py", line 867, in getaddrinfo
    return await self.run_in_executor(
           ^^^^^^^^^^^^^^^^^^^^^^^^^^^
  File "/usr/lib/python3.11/concurrent/futures/thread.py", line 58, in run
    result = self.fn(*self.args, **self.kwargs)
             ^^^^^^^^^^^^^^^^^^^^^^^^^^^^^^^^^^
  File "/usr/lib/python3.11/socket.py", line 962, in getaddrinfo
    for res in _socket.getaddrinfo(host, port, family, type, proto, flags):
               ^^^^^^^^^^^^^^^^^^^^^^^^^^^^^^^^^^^^^^^^^^^^^^^^^^^^^^^^^^^
socket.gaierror: [Errno -3] Temporary failure in name resolution

The above exception was the direct cause of the following exception:

Traceback (most recent call last):
  File "/home/oai/share/rss-ai/backend/main.py", line 206, in fetch_and_parse
    async with session.get(rss_url) as resp:
  File "/opt/pyvenv/lib/python3.11/site-packages/aiohttp/client.py", line 1197, in __aenter__
    self._resp = await self._coro
                 ^^^^^^^^^^^^^^^^
  File "/opt/pyvenv/lib/python3.11/site-packages/aiohttp/client.py", line 581, in _request
    conn = await self._connector.connect(
           ^^^^^^^^^^^^^^^^^^^^^^^^^^^^^^
  File "/opt/pyvenv/lib/python3.11/site-packages/aiohttp/connector.py", line 544, in connect
    proto = await self._create_connection(req, traces, timeout)
            ^^^^^^^^^^^^^^^^^^^^^^^^^^^^^^^^^^^^^^^^^^^^^^^^^^^
  File "/opt/pyvenv/lib/python3.11/site-packages/aiohttp/connector.py", line 944, in _create_connection
    _, proto = await self._create_direct_connection(req, traces, timeout)
               ^^^^^^^^^^^^^^^^^^^^^^^^^^^^^^^^^^^^^^^^^^^^^^^^^^^^^^^^^^
  File "/opt/pyvenv/lib/python3.11/site-packages/aiohttp/connector.py", line 1209, in _create_direct_connection
    raise ClientConnectorError(req.connection_key, exc) from exc
aiohttp.client_exceptions.ClientConnectorError: Cannot connect to host example.com:80 ssl:default [Temporary failure in name resolution]
